<?xml version="1.0" ?>
<!-- =================================================================================== -->
<!-- |    This document was autogenerated by xacro from robot.xacro                    | -->
<!-- |    EDITING THIS FILE BY HAND IS NOT RECOMMENDED                                 | -->
<!-- =================================================================================== -->
<!-- =================================================================================== -->
<!-- |    Complete Robot Description for Agibot G1                                     | -->
<!-- |    This file includes the base robot structure and both arms                    | -->
<!-- =================================================================================== -->
<robot name="Agibot G1">
  <!-- Base links -->
  <link name="base_footprint"/>
  <joint name="base_footprint_joint" type="fixed">
    <origin xyz="0 0 0.211"/>
    <parent link="base_footprint"/>
    <child link="base_link"/>
  </joint>
  <link name="base_link">
    <inertial>
      <origin xyz="-0.00804486971267798 0 -0.120076754329413"/>
      <mass value="65.2085382238952"/>
      <inertia ixx="0.386955641760608" ixy="0.000135417314593726" ixz="0.00669301645720665" iyy="0.366800407621218" iyz="0.000105713634260505" izz="0.546852919828475"/>
    </inertial>
    <visual>
      <geometry>
        <mesh filename="../meshes/base/base.obj"/>
      </geometry>
    </visual>
    <collision>
      <origin xyz="-0.10913086 0.0 0.5971875"/>
      <geometry>
        <box size="0.29833984 0.3376392 1.0"/>
      </geometry>
    </collision>
    <collision>
      <origin xyz="0.01 0.0 -0.045"/>
      <geometry>
        <box size="0.5796094 0.449 0.27073438"/>
      </geometry>
    </collision>
    <collision>
      <origin xyz="0.22 0.14 -0.175245"/>
      <geometry>
        <sphere radius="0.038"/>
      </geometry>
    </collision>
    <collision>
      <origin xyz="0.22 -0.14 -0.175245"/>
      <geometry>
        <sphere radius="0.038"/>
      </geometry>
    </collision>
    <collision>
      <origin xyz="-0.18 0.14 -0.175245"/>
      <geometry>
        <sphere radius="0.038"/>
      </geometry>
    </collision>
    <collision>
      <origin xyz="-0.18 -0.14 -0.175245"/>
      <geometry>
        <sphere radius="0.038"/>
      </geometry>
    </collision>
  </link>
  <link name="body_link1">
    <inertial>
      <origin xyz="0.0338351537064605 -0.00248044044451858 0.000838431095422365"/>
      <mass value="3.26275452360108"/>
      <inertia ixx="0.0128301877197417" ixy="8.24967996575627e-06" ixz="1.38254543337324e-05" iyy="0.006104110250297" iyz="-7.99392548994692e-06" izz="0.0111721084996867"/>
    </inertial>
    <visual>
      <geometry>
        <mesh filename="../meshes/base/body_link1.obj"/>
      </geometry>
    </visual>
    <collision>
      <origin xyz="0.10278320000000002 0.1 -0.013671875"/>
      <geometry>
        <box size="0.16064453 0.05555534399999999 0.1328125"/>
      </geometry>
    </collision>
    <collision>
      <origin xyz="0.10180664 -0.1 0.0"/>
      <geometry>
        <box size="0.16259765999999998 0.04375648500000001 0.16015625"/>
      </geometry>
    </collision>
  </link>
  <link name="body_link2">
    <inertial>
      <origin xyz="-0.000484180179482319 -0.193733558855111 -0.00124011422952511"/>
      <mass value="7.53199207979272"/>
      <inertia ixx="0.0788874639537613" ixy="5.46530938736686E-10" ixz="0.00286825206797472" iyy="0.0515041942141216" iyz="3.46275348004213E-07" izz="0.0448953474115628"/>
    </inertial>
    <visual>
      <geometry>
        <mesh filename="../meshes/base/body_link2.obj"/>
      </geometry>
      <origin rpy="0.0 0.0 -1.5707963267948966"/>
    </visual>
    <collision>
      <origin xyz="0.0068359375 -0.00034356117 0.0"/>
      <geometry>
        <cylinder length="0.08697056999999997" radius="0.09662318"/>
      </geometry>
    </collision>
    <collision>
      <origin xyz="0.0068359375 -0.00034356117 0.043485284999999985"/>
      <geometry>
        <sphere radius="0.09662318"/>
      </geometry>
    </collision>
    <collision>
      <origin xyz="0.0068359375 -0.00034356117 -0.043485284999999985"/>
      <geometry>
        <sphere radius="0.09662318"/>
      </geometry>
    </collision>
    <collision>
      <origin rpy="0.0 0.0 -1.5708" xyz="0.008 -0.248 0.0"/>
      <geometry>
        <box size="0.34570312 0.18107724 0.3125"/>
      </geometry>
    </collision>
  </link>
  <!-- Base joints -->
  <joint name="body_joint1" type="prismatic">
    <parent link="base_link"/>
    <child link="body_link1"/>
    <origin xyz="0.0 0.0 0.4285"/>
    <axis xyz="0.0 0.0 1.0"/>
    <limit effort="1000" lower="0.0" upper="0.5" velocity="0.1"/>
  </joint>
  <joint name="body_joint2" type="revolute">
    <parent link="body_link1"/>
    <child link="body_link2"/>
    <origin rpy="-1.5707963267948966 0.0 0.0" xyz="0.131 0.0 0.0"/>
    <axis xyz="0.0 0.0 1.0"/>
    <limit effort="100.0" lower="0.0" upper="1.5707963267948966" velocity="0.5"/>
  </joint>
  <!-- Arm base link -->
  <link name="left_base_link">
    <inertial>
      <origin xyz="0.00020641 -0.00057488 0.032296"/>
      <mass value="0.37595"/>
      <inertia ixx="0.00024335" ixy="1.2188e-06" ixz="2.4281e-06" iyy="0.00024039" iyz="-6.6932e-06" izz="0.00032195"/>
    </inertial>
    <visual>
      <geometry>
        <mesh filename="../meshes/arm/base_link.obj"/>
      </geometry>
    </visual>
  </link>
  <!-- Arm links -->
  <link name="left_link1">
    <inertial>
      <origin xyz="0.0012655 -0.00043778 -0.018388"/>
      <mass value="0.4936"/>
      <inertia ixx="0.00075396" ixy="-2.4144e-06" ixz="-1.8364e-06" iyy="0.00065755" iyz="1.2174e-06" izz="0.00031848"/>
    </inertial>
    <visual>
      <geometry>
        <mesh filename="../meshes/arm/link1.obj"/>
      </geometry>
    </visual>
    <collision>
      <geometry>
        <cylinder length="0.16642063483595848" radius="0.05579268228774888"/>
      </geometry>
      <origin rpy="0.0 0.0 -1.2566370614359172" xyz="0.0026814433577366636 0.0006133775157398935 -0.04071124829351902"/>
    </collision>
  </link>
  <link name="left_link2">
    <inertial>
      <origin xyz="-0.00044207 -0.082298 0.00019486"/>
      <mass value="0.46245"/>
      <inertia ixx="0.00065719" ixy="3.7112e-07" ixz="-3.6668e-06" iyy="0.00043459" iyz="-2.517e-05" izz="0.00072571"/>
    </inertial>
    <visual>
      <geometry>
        <mesh filename="../meshes/arm/link2.obj"/>
      </geometry>
    </visual>
    <collision>
      <origin rpy="1.5707963267948966 0 0" xyz="0.0 -0.044062052 0.0009765625"/>
      <geometry>
        <cylinder length="0.18085919" radius="0.06302423"/>
      </geometry>
    </collision>
  </link>
  <link name="left_link3">
    <inertial>
      <origin xyz="0.0010558 4.4416e-05 -0.056128"/>
      <mass value="0.50026"/>
      <inertia ixx="0.0013016" ixy="3.1401e-06" ixz="1.4255e-05" iyy="0.001427" iyz="2.4361e-05" izz="0.00033587"/>
    </inertial>
    <visual>
      <geometry>
        <mesh filename="../meshes/arm/link3.obj"/>
      </geometry>
    </visual>
    <collision>
      <origin xyz="0.0006559932284637068 -2.2628975236450855e-05 -0.07219303026795387"/>
      <geometry>
        <cylinder length="0.22061403840780258" radius="0.05216156143823925"/>
      </geometry>
    </collision>
  </link>
  <link name="left_link4">
    <inertial>
      <origin xyz="2.4212e-05 -0.06248 0.002536"/>
      <mass value="0.27473"/>
      <inertia ixx="0.00029283" ixy="4.5586e-07" ixz="5.8042e-08" iyy="0.00018852" iyz="-1.116e-06" izz="0.00031238"/>
    </inertial>
    <visual>
      <geometry>
        <mesh filename="../meshes/arm/link4.obj"/>
      </geometry>
    </visual>
    <collision>
      <origin rpy="1.5707963267948966 0 0" xyz="0.0 -0.03817895 -0.0043945312"/>
      <geometry>
        <cylinder length="0.154955404" radius="0.057891708"/>
      </geometry>
    </collision>
  </link>
  <link name="left_link5">
    <inertial>
      <origin xyz="2.6223e-06 -0.00023041 -0.024141"/>
      <mass value="0.25139"/>
      <inertia ixx="0.00023516" ixy="-6.5868e-09" ixz="-1.9428e-08" iyy="0.00028807" iyz="-1.2108e-05" izz="0.00013068"/>
    </inertial>
    <visual>
      <geometry>
        <mesh filename="../meshes/arm/link5.obj"/>
      </geometry>
    </visual>
    <collision>
      <origin xyz="-0.00022255510134868567 -4.227476414728204e-05 -0.03344946540892124"/>
      <geometry>
        <cylinder length="0.13423806056380272" radius="0.04562028545392604"/>
      </geometry>
    </collision>
  </link>
  <link name="left_link6">
    <inertial>
      <origin xyz="5.0382e-06 -0.086696 0.002556"/>
      <mass value="0.26634"/>
      <inertia ixx="0.00031434" ixy="-1.2113e-09" ixz="1.0011e-07" iyy="0.00014464" iyz="-2.033e-05" izz="0.00032449"/>
    </inertial>
    <visual>
      <geometry>
        <mesh filename="../meshes/arm/link6.obj"/>
      </geometry>
    </visual>
    <collision>
      <origin rpy="0.0 -1.4835107730827122 -1.56897465223053" xyz="-1.7782549414354032e-05 -0.05507596972928094 -0.0017447156928267265"/>
      <geometry>
        <cylinder length="0.18272488500982115" radius="0.04857149291994264"/>
      </geometry>
    </collision>
  </link>
  <link name="left_end_link">
    <inertial>
      <origin xyz="-7.5134e-05 -0.00024521 -0.016705"/>
      <mass value="0.06158"/>
      <inertia ixx="1.8407e-05" ixy="3.4818e-08" ixz="-3.2902e-09" iyy="1.818e-05" iyz="1.1326e-07" izz="2.8547e-05"/>
    </inertial>
    <visual>
      <geometry>
        <mesh filename="../meshes/arm/link7.obj"/>
      </geometry>
    </visual>
    <collision>
      <origin rpy="3.141592653589793 -1.2246467991473532e-16 3.141592653589793" xyz="-4.552953707661759e-05 -0.002300474691790042 -0.02249999972991645"/>
      <geometry>
        <cylinder length="0.045999998692423105" radius="0.030799950382754494"/>
      </geometry>
    </collision>
  </link>
  <!-- Arm joints -->
  <joint name="left_joint1" type="revolute">
    <parent link="left_base_link"/>
    <child link="left_link1"/>
    <origin xyz="0.0 0.0 0.1859"/>
    <axis xyz="0.0 0.0 1.0"/>
    <limit effort="60.0" lower="-3.14" upper="3.14" velocity="3.14"/>
  </joint>
  <joint name="left_joint2" type="revolute">
    <parent link="left_link1"/>
    <child link="left_link2"/>
    <origin rpy="-1.5707963267948966 0.0 1.5707963267948966" xyz="0.0 0.0 0.0"/>
    <axis xyz="0.0 0.0 1.0"/>
    <limit effort="60.0" lower="-2.09" upper="1.48" velocity="3.14"/>
  </joint>
  <joint name="left_joint3" type="revolute">
    <parent link="left_link2"/>
    <child link="left_link3"/>
    <origin rpy="-1.5707963267948966 1.5707963267948966 3.141592653589793" xyz="0.0 -0.305 0.0"/>
    <axis xyz="0.0 0.0 1.0"/>
    <limit effort="60.0" lower="-3.10" upper="3.10" velocity="3.14"/>
  </joint>
  <joint name="left_joint4" type="revolute">
    <parent link="left_link3"/>
    <child link="left_link4"/>
    <origin rpy="-1.5707963267948966 0.0 3.141592653589793" xyz="0.0 0.0 0.0"/>
    <axis xyz="0.0 0.0 1.0"/>
    <limit effort="60.0" lower="-1.48" upper="1.48" velocity="3.14"/>
  </joint>
  <joint name="left_joint5" type="revolute">
    <parent link="left_link4"/>
    <child link="left_link5"/>
    <origin rpy="-1.5707963267948966 0.0 -3.141592653589793" xyz="0.0 -0.1975 0.0"/>
    <axis xyz="0.0 0.0 1.0"/>
    <limit effort="30.0" lower="-3.10" upper="3.10" velocity="3.14"/>
  </joint>
  <joint name="left_joint6" type="revolute">
    <parent link="left_link5"/>
    <child link="left_link6"/>
    <origin rpy="-1.5707963267948966 0.0 0.0" xyz="0.0 0.0 0.0"/>
    <axis xyz="0.0 0.0 1.0"/>
    <limit effort="30.0" lower="-1.74" upper="1.74" velocity="3.14"/>
  </joint>
  <joint name="left_joint7" type="revolute">
    <origin rpy="1.5707963267948966 0.0 0.0" xyz="0.0 -0.1805 0.0"/>
    <parent link="left_link6"/>
    <child link="left_end_link"/>
    <axis xyz="0.0 0.0 1.0"/>
    <limit effort="30.0" lower="-3.10" upper="3.10" velocity="3.14"/>
  </joint>


  <!-- Arm base links -->
  <link name="arm_base"/>
  <!-- Arm base joints -->
  <joint name="arm_base_joint" type="fixed">
    <parent link="body_link2"/>
    <child link="arm_base"/>
    <origin rpy="1.5707963267948966 0.0 0.0" xyz="0.0 -0.305 0.0"/>
  </joint>
  <joint name="left_base_joint" type="fixed">
    <parent link="arm_base"/>
    <child link="left_base_link"/>
    <origin rpy="-1.5707963267948966 0.0 0.0" xyz="0.0 0.025 0.0"/>
  </joint>


  <!-- <link name="left_eef"/>
  <joint name="left_eef_joint" type="fixed">
    <origin xyz="0.0 0.0 0.15"/>
    <parent link="left_end_link"/>
    <child link="left_eef"/>
  </joint> -->
</robot>
